..F
======================================================================
FAIL: test_fail (__main__.Tests)
----------------------------------------------------------------------
Traceback (most recent call last):
  File "/home/peter/dev/proof_of_concept/tests/test.py", line 12, in test_fail
    self.assertEqual(astro.test_func(0), 0)
AssertionError: 85 != 0

----------------------------------------------------------------------
Ran 3 tests in 0.000s

FAILED (failures=1)
